<?xml version="1.0" ?>
<!-- =================================================================================== -->
<!-- |    This document was autogenerated by xacro from urdf/iiwa14.urdf.xacro         | -->
<!-- |    EDITING THIS FILE BY HAND IS NOT RECOMMENDED                                 | -->
<!-- =================================================================================== -->
<robot name="iiwa14">
  <link name="base_link"/>
  <joint name="base_joint" type="fixed">
    <origin rpy="0 0 0" xyz="0 0 0"/>
    <parent link="base_link"/>
    <child link="link_0"/>
  </joint>
  <link name="link_0">
    <inertial>
      <origin rpy="0 0 0" xyz="-0.1 0 0.07"/>
      <mass value="5"/>
      <inertia ixx="0.05" ixy="0" ixz="0" iyy="0.06" iyz="0" izz="0.03"/>
    </inertial>
    <visual>
      <origin rpy="0 0 0" xyz="0 0 0"/>
      <geometry>
        <mesh filename="meshes/visual/link_0.stl"/>
      </geometry>
    </visual>
    <collision>
      <origin rpy="0 0 0" xyz="0 0 0"/>
      <geometry>
        <mesh filename="meshes/collision/link_0_s.stl"/>
      </geometry>
    </collision>
    <self_collision_checking>
      <origin rpy="0 0 0" xyz="0 0 0"/>
      <geometry>
        <capsule length="0.25" radius="0.15"/>
      </geometry>
    </self_collision_checking>
  </link>
  <!-- joint between link_0 and link_1 -->
  <joint name="joint_0" type="revolute">
    <parent link="link_0"/>
    <child link="link_1"/>
    <origin rpy="0 0 0" xyz="0 0 0.17"/>
    <axis xyz="0 0 1"/>
    <limit effort="300" lower="-2.9670597283903604" upper="2.9670597283903604" velocity="10"/>
    <safety_controller k_position="100" k_velocity="2" soft_lower_limit="-2.9321531433504737" soft_upper_limit="2.9321531433504737"/>
    <dynamics damping="0.0" friction="0.0"/>
  </joint>
  <link name="link_1">
    <inertial>
      <origin rpy="0 0 0" xyz="0 -0.03 0.12"/>
      <mass value="4"/>
      <inertia ixx="0.1" ixy="0" ixz="0" iyy="0.09" iyz="0" izz="0.02"/>
    </inertial>
    <visual>
      <origin rpy="0 0 0" xyz="0 0 0"/>
      <geometry>
        <mesh filename="meshes/visual/link_1.stl"/>
      </geometry>
    </visual>
    <collision>
      <origin rpy="0 0 0" xyz="0 0 0"/>
      <geometry>
        <mesh filename="meshes/collision/link_1_s.stl"/>
      </geometry>
    </collision>
  </link>
  <!-- joint between link_1 and link_2 -->
  <joint name="joint_1" type="revolute">
    <parent link="link_1"/>
    <child link="link_2"/>
    <origin rpy="1.5707963267948966   0 3.141592653589793" xyz="0 0 0.2025"/>
    <axis xyz="0 0 1"/>
    <limit effort="300" lower="-2.0943951023931953" upper="2.0943951023931953" velocity="10"/>
    <safety_controller k_position="100" k_velocity="2" soft_lower_limit="-2.0594885173533086" soft_upper_limit="2.0594885173533086"/>
    <dynamics damping="0.0" friction="0.0"/>
  </joint>
  <link name="link_2">
    <inertial>
      <origin rpy="0 0 0" xyz="0.0003 0.059 0.042"/>
      <mass value="4"/>
      <inertia ixx="0.05" ixy="0" ixz="0" iyy="0.018" iyz="0" izz="0.044"/>
    </inertial>
    <visual>
      <origin rpy="0 0 0" xyz="0 0 0"/>
      <geometry>
        <mesh filename="meshes/visual/link_2.stl"/>
      </geometry>
    </visual>
    <collision>
      <origin rpy="0 0 0" xyz="0 0 0"/>
      <geometry>
        <mesh filename="meshes/collision/link_2_s.stl"/>
      </geometry>
    </collision>
  </link>
  <!-- joint between link_2 and link_3 -->
  <joint name="joint_2" type="revolute">
    <parent link="link_2"/>
    <child link="link_3"/>
    <origin rpy="1.5707963267948966 0 3.141592653589793" xyz="0 0.2045 0"/>
    <axis xyz="0 0 1"/>
    <limit effort="300" lower="-2.9670597283903604" upper="2.9670597283903604" velocity="10"/>
    <safety_controller k_position="100" k_velocity="2" soft_lower_limit="-2.9321531433504737" soft_upper_limit="2.9321531433504737"/>
    <dynamics damping="0.0" friction="0.0"/>
  </joint>
  <link name="link_3">
    <inertial>
      <origin rpy="0 0 0" xyz="0 0.03 0.13"/>
      <mass value="3"/>
      <inertia ixx="0.08" ixy="0" ixz="0" iyy="0.075" iyz="0" izz="0.01"/>
    </inertial>
    <visual>
      <origin rpy="0 0 0" xyz="0 0 0"/>
      <geometry>
        <mesh filename="meshes/visual/link_3.stl"/>
      </geometry>
    </visual>
    <collision>
      <origin rpy="0 0 0" xyz="0 0 0"/>
      <geometry>
        <mesh filename="meshes/collision/link_3_s.stl"/>
      </geometry>
    </collision>
  </link>
  <!-- joint between link_3 and link_4 -->
  <joint name="joint_3" type="revolute">
    <parent link="link_3"/>
    <child link="link_4"/>
    <origin rpy="1.5707963267948966 0 0" xyz="0 0 0.2155"/>
    <axis xyz="0 0 1"/>
    <limit effort="300" lower="-2.0943951023931953" upper="2.0943951023931953" velocity="10"/>
    <safety_controller k_position="100" k_velocity="2" soft_lower_limit="-2.0594885173533086" soft_upper_limit="2.0594885173533086"/>
    <dynamics damping="0.0" friction="0.0"/>
  </joint>
  <link name="link_4">
    <inertial>
      <origin rpy="0 0 0" xyz="0 0.067 0.034"/>
      <mass value="2.7"/>
      <inertia ixx="0.03" ixy="0" ixz="0" iyy="0.01" iyz="0" izz="0.029"/>
    </inertial>
    <visual>
      <origin rpy="0 0 0" xyz="0 0 0"/>
      <geometry>
        <mesh filename="meshes/visual/link_4.stl"/>
      </geometry>
    </visual>
    <collision>
      <origin rpy="0 0 0" xyz="0 0 0"/>
      <geometry>
        <mesh filename="meshes/collision/link_4_s.stl"/>
      </geometry>
    </collision>
  </link>
  <!-- joint between link_4 and link_5 -->
  <joint name="joint_4" type="revolute">
    <parent link="link_4"/>
    <child link="link_5"/>
    <origin rpy="-1.5707963267948966 3.141592653589793 0" xyz="0 0.1845 0"/>
    <axis xyz="0 0 1"/>
    <limit effort="300" lower="-2.9670597283903604" upper="2.9670597283903604" velocity="10"/>
    <safety_controller k_position="100" k_velocity="2" soft_lower_limit="-2.9321531433504737" soft_upper_limit="2.9321531433504737"/>
    <dynamics damping="0.0" friction="0.0"/>
  </joint>
  <link name="link_5">
    <inertial>
      <origin rpy="0 0 0" xyz="0.0001 0.021 0.076"/>
      <mass value="1.7"/>
      <inertia ixx="0.02" ixy="0" ixz="0" iyy="0.018" iyz="0" izz="0.005"/>
    </inertial>
    <visual>
      <origin rpy="0 0 0" xyz="0 0 0"/>
      <geometry>
        <mesh filename="meshes/visual/link_5.stl"/>
      </geometry>
    </visual>
    <collision>
      <origin rpy="0 0 0" xyz="0 0 0"/>
      <geometry>
        <mesh filename="meshes/collision/link_5_s.stl"/>
      </geometry>
    </collision>
  </link>
  <!-- joint between link_5 and link_6 -->
  <joint name="joint_5" type="revolute">
    <parent link="link_5"/>
    <child link="link_6"/>
    <origin rpy="1.5707963267948966 0 0" xyz="0 0 0.2155"/>
    <axis xyz="0 0 1"/>
    <limit effort="300" lower="-2.0943951023931953" upper="2.0943951023931953" velocity="10"/>
    <safety_controller k_position="100" k_velocity="2" soft_lower_limit="-2.0594885173533086" soft_upper_limit="2.0594885173533086"/>
    <dynamics damping="0.0" friction="0.0"/>
  </joint>
  <link name="link_6">
    <inertial>
      <origin rpy="0 0 0" xyz="0 0.0006 0.0004"/>
      <mass value="1.8"/>
      <inertia ixx="0.025" ixy="0" ixz="0" iyy="0.0136" iyz="0" izz="0.0247"/>
    </inertial>
    <visual>
      <origin rpy="0 0 0" xyz="0 0 0"/>
      <geometry>
        <mesh filename="meshes/visual/link_6.stl"/>
      </geometry>
    </visual>
    <collision>
      <origin rpy="0 0 0" xyz="0 0 0"/>
      <geometry>
        <mesh filename="meshes/collision/link_6_s.stl"/>
      </geometry>
    </collision>
  </link>
  <!-- joint between link_6 and link_7 -->
  <joint name="joint_6" type="revolute">
    <parent link="link_6"/>
    <child link="link_7"/>
    <origin rpy="-1.5707963267948966 3.141592653589793 0" xyz="0 0.081 0"/>
    <axis xyz="0 0 1"/>
    <limit effort="300" lower="-3.0543261909900763" upper="3.0543261909900763" velocity="10"/>
    <safety_controller k_position="100" k_velocity="2" soft_lower_limit="-3.01941960595019" soft_upper_limit="3.01941960595019"/>
    <dynamics damping="0.0" friction="0.0"/>
  </joint>
  <link name="link_7">
    <inertial>
      <origin rpy="0 0 0" xyz="0 0 0.02"/>
      <mass value="0.42857142857142855"/>
      <inertia ixx="0.01" ixy="0" ixz="0" iyy="0.01" iyz="0" izz="0.01"/>
    </inertial>
    <visual>
      <origin rpy="0 0 0" xyz="0 0 0"/>
      <geometry>
        <mesh filename="meshes/visual/link_7.stl"/>
      </geometry>
    </visual>
    <collision>
      <origin rpy="0 0 0" xyz="0 0 0"/>
      <geometry>
        <mesh filename="meshes/collision/link_7_s.stl"/>
      </geometry>
    </collision>
  </link>
  <joint name="joint_ee" type="fixed">
    <parent link="link_7"/>
    <child link="gripper_base_link"/>
    <origin rpy="0 0 0" xyz="0 0 0.045"/>
  </joint>

  <link name="gripper_base_link">
    <inertial>
      <origin rpy="0 0 0" xyz="-4.898915958379213e-05 2.84756960271082e-06 0.06811082379774974"/>
      <mass value="1.2646523179240972"/>
      <inertia ixx="0.001504" ixy="-0.0" ixz="-3e-06" iyy="0.001812" iyz="0.0" izz="0.001053"/>
    </inertial>
    <visual>
      <origin rpy="0 0 0" xyz="0 0 0"/>
      <geometry>
        <mesh filename="meshes/gripper_base_link.stl"/>
      </geometry>
    </visual>
    <collision>
      <origin rpy="0 0 0" xyz="0 0 0"/>
      <geometry>
        <mesh filename="meshes/gripper_base_link.stl"/>
      </geometry>
    </collision>
  </link>
  <link name="right_finger_link">
    <inertial>
      <origin rpy="0 0 0" xyz="0.017874296677847158 0.02949104051991925 0.01523421548622829"/>
      <mass value="0.023219383355922288"/>
      <inertia ixx="6e-06" ixy="-0.0" ixz="1e-06" iyy="5e-06" iyz="-0.0" izz="2e-06"/>
    </inertial>
    <visual>
      <origin rpy="0 0 0" xyz="0.054361 0.029494 -0.12005"/>
      <geometry>
        <mesh filename="meshes/right_finger_link.stl"/>
      </geometry>
    </visual>
    <collision name="right_finger_collision">
      <origin rpy="0 0 0" xyz="0.054361 0.029494 -0.12005"/>
      <geometry>
        <mesh filename="meshes/right_finger_link.stl"/>
      </geometry>
    </collision>
  </link>
  <link name="left_finger_link">
    <inertial>
      <origin rpy="0 0 0" xyz="0.004247703322119739 0.029496959480080673 0.015234215486237948"/>
      <mass value="0.023219383355922288"/>
      <inertia ixx="6e-06" ixy="-0.0" ixz="-1e-06" iyy="5e-06" iyz="0.0" izz="2e-06"/>
    </inertial>
    <visual>
      <origin rpy="0 0 0" xyz="-0.032239 0.029494 -0.12005"/>
      <geometry>
        <mesh filename="meshes/left_finger_link.stl"/>
      </geometry>
    </visual>
    <collision name="left_finger_collision">
      <origin rpy="0 0 0" xyz="-0.032239 0.029494 -0.12005"/>
      <geometry>
        <mesh filename="meshes/left_finger_link.stl"/>
      </geometry>
    </collision>
  </link>
  <!-- <joint name="left_finger_joint" type="prismatic"> -->
  <joint name="left_finger_joint" type="fixed">
    <origin rpy="0 0 0" xyz="0.0 -0.03 0.236"/>
    <parent link="gripper_base_link"/>
    <child link="left_finger_link"/>
    <axis xyz="-1.0 0.0 0.0"/>
    <!-- <limit effort="140" lower="0.0" upper="0.019" velocity="0.45"/> -->
  </joint>
  <!-- <joint name="right_finger_joint" type="prismatic"> -->
  <joint name="right_finger_joint" type="fixed">
    <origin rpy="0 0 0" xyz="-0.022 -0.03 0.236"/>
    <parent link="gripper_base_link"/>
    <child link="right_finger_link"/>
    <axis xyz="1.0 0.0 0.0"/>
    <!-- <limit effort="140" lower="-0.019" upper="0.019" velocity="0.45"/>
    <mimic joint="left_finger_joint" multiplier="1.0"/> -->
  </joint>

  <link name="gripper_base_target">
    <visual>
      <geometry>
        <sphere radius="0.01"/>
      </geometry>
    </visual>
  </link>
  <joint name="gripper_parent_to_target" type="fixed">
    <parent link="gripper_base_link"/>
    <child link="gripper_base_target"/>
    <origin rpy="0 0 1.57079632679" xyz="0 0 0.07"/>
  </joint>

</robot>
