<?xml version="1.0" ?>
<!-- =================================================================================== -->
<!-- |    This document was autogenerated by xacro from gen3_robotiq_2f_85.xacro       | -->
<!-- |    EDITING THIS FILE BY HAND IS NOT RECOMMENDED                                 | -->
<!-- =================================================================================== -->
<robot name="gen3_robotiq_2f_85">
  <link name="base_link"/>
  <joint name="base_joint" type="fixed">
    <origin rpy="0 0 0" xyz="0 0 0"/>
    <parent link="base_link"/>
    <child link="base_link_inertia"/>
  </joint>

  <!-- Run the macros -->
  <link name="base_link_inertia">
    <inertial>
      <origin rpy="0 0 0" xyz="-0.000648 -0.000166 0.084487"/>
      <mass value="1.697"/>
      <inertia ixx="0.004622" ixy="9E-06" ixz="6E-05" iyy="0.004495" iyz="9E-06" izz="0.002079"/>
    </inertial>
    <visual>
      <origin rpy="0 0 0" xyz="0 0 0"/>
      <geometry>
        <mesh filename="meshes/7dof/base_link.STL"/>
      </geometry>
      <material name="">
        <color rgba="0.75294 0.75294 0.75294 1"/>
      </material>
    </visual>
    <collision>
      <origin rpy="0 0 0" xyz="0 0 0"/>
      <geometry>
        <mesh filename="meshes/7dof/base_link.STL"/>
      </geometry>
    </collision>
  </link>
  <link name="shoulder_link">
    <inertial>
      <origin rpy="0 0 0" xyz="-2.3E-05 -0.010364 -0.07336"/>
      <mass value="1.3773"/>
      <inertia ixx="0.00457" ixy="1E-06" ixz="2E-06" iyy="0.004831" iyz="0.000448" izz="0.001409"/>
    </inertial>
    <visual>
      <origin rpy="0 0 0" xyz="0 0 0"/>
      <geometry>
        <mesh filename="meshes/7dof/shoulder_link.STL"/>
      </geometry>
      <material name="">
        <color rgba="0.75294 0.75294 0.75294 1"/>
      </material>
    </visual>
    <collision>
      <origin rpy="0 0 0" xyz="0 0 0"/>
      <geometry>
        <mesh filename="meshes/7dof/shoulder_link.STL"/>
      </geometry>
    </collision>
  </link>
  <joint name="joint_1" type="revolute">
    <!-- <origin rpy="3.1416 2.7629E-18 -4.9305E-36" xyz="0 0 0.15643"/> -->
    <origin rpy="3.1416 2.7629E-18 -4.9305E-36" xyz="0 0 0.17643"/>
    <parent link="base_link"/>
    <child link="shoulder_link"/>
    <axis xyz="0 0 1"/>
    <limit effort="39" lower="-3.14" upper="3.14" velocity="1.3963"/>
  </joint>
  <link name="half_arm_1_link">
    <inertial>
      <origin rpy="0 0 0" xyz="-4.4E-05 -0.09958 -0.013278"/>
      <mass value="1.1636"/>
      <inertia ixx="0.011088" ixy="5E-06" ixz="0" iyy="0.001072" iyz="-0.000691" izz="0.011255"/>
    </inertial>
    <visual>
      <origin rpy="0 0 0" xyz="0 0 0"/>
      <geometry>
        <mesh filename="meshes/7dof/half_arm_1_link.STL"/>
      </geometry>
      <material name="">
        <color rgba="0.75294 0.75294 0.75294 1"/>
      </material>
    </visual>
    <collision>
      <origin rpy="0 0 0" xyz="0 0 0"/>
      <geometry>
        <mesh filename="meshes/7dof/half_arm_1_link.STL"/>
      </geometry>
    </collision>
  </link>
  <joint name="joint_2" type="revolute">
    <origin rpy="1.5708 2.1343E-17 -1.1102E-16" xyz="0 0.005375 -0.12838"/>
    <parent link="shoulder_link"/>
    <child link="half_arm_1_link"/>
    <axis xyz="0 0 1"/>
    <limit effort="39" lower="-2.24" upper="2.24" velocity="1.3963"/>
  </joint>
  <link name="half_arm_2_link">
    <inertial>
      <origin rpy="0 0 0" xyz="-4.4E-05 -0.006641 -0.117892"/>
      <mass value="1.1636"/>
      <inertia ixx="0.010932" ixy="0" ixz="-7E-06" iyy="0.011127" iyz="0.000606" izz="0.001043"/>
    </inertial>
    <visual>
      <origin rpy="0 0 0" xyz="0 0 0"/>
      <geometry>
        <mesh filename="meshes/7dof/half_arm_2_link.STL"/>
      </geometry>
      <material name="">
        <color rgba="0.75294 0.75294 0.75294 1"/>
      </material>
    </visual>
    <collision>
      <origin rpy="0 0 0" xyz="0 0 0"/>
      <geometry>
        <mesh filename="meshes/7dof/half_arm_2_link.STL"/>
      </geometry>
    </collision>
  </link>
  <joint name="joint_3" type="revolute">
    <origin rpy="-1.5708 1.2326E-32 -2.9122E-16" xyz="0 -0.21038 -0.006375"/>
    <parent link="half_arm_1_link"/>
    <child link="half_arm_2_link"/>
    <axis xyz="0 0 1"/>
    <limit effort="39" lower="-3.14" upper="3.14" velocity="1.3963"/>
  </joint>
  <link name="forearm_link">
    <inertial>
      <origin rpy="0 0 0" xyz="-1.8E-05 -0.075478 -0.015006"/>
      <mass value="0.9302"/>
      <inertia ixx="0.008147" ixy="-1E-06" ixz="0" iyy="0.000631" iyz="-0.0005" izz="0.008316"/>
    </inertial>
    <visual>
      <origin rpy="0 0 0" xyz="0 0 0"/>
      <geometry>
        <mesh filename="meshes/7dof/forearm_link.STL"/>
      </geometry>
      <material name="">
        <color rgba="0.75294 0.75294 0.75294 1"/>
      </material>
    </visual>
    <collision>
      <origin rpy="0 0 0" xyz="0 0 0"/>
      <geometry>
        <mesh filename="meshes/7dof/forearm_link.STL"/>
      </geometry>
    </collision>
  </link>
  <joint name="joint_4" type="revolute">
    <origin rpy="1.5708 -6.6954E-17 -1.6653E-16" xyz="0 0.006375 -0.21038"/>
    <parent link="half_arm_2_link"/>
    <child link="forearm_link"/>
    <axis xyz="0 0 1"/>
    <limit effort="39" lower="-2.57" upper="2.57" velocity="1.3963"/>
  </joint>
  <link name="spherical_wrist_1_link">
    <inertial>
      <origin rpy="0 0 0" xyz="1E-06 -0.009432 -0.063883"/>
      <mass value="0.6781"/>
      <inertia ixx="0.001596" ixy="0" ixz="0" iyy="0.001607" iyz="0.000256" izz="0.000399"/>
    </inertial>
    <visual>
      <origin rpy="0 0 0" xyz="0 0 0"/>
      <geometry>
        <mesh filename="meshes/7dof/spherical_wrist_1_link.STL"/>
      </geometry>
      <material name="">
        <color rgba="0.75294 0.75294 0.75294 1"/>
      </material>
    </visual>
    <collision>
      <origin rpy="0 0 0" xyz="0 0 0"/>
      <geometry>
        <mesh filename="meshes/7dof/spherical_wrist_1_link.STL"/>
      </geometry>
    </collision>
  </link>
  <joint name="joint_5" type="revolute">
    <origin rpy="-1.5708 2.2204E-16 -6.373E-17" xyz="0 -0.20843 -0.006375"/>
    <parent link="forearm_link"/>
    <child link="spherical_wrist_1_link"/>
    <axis xyz="0 0 1"/>
    <limit effort="9" lower="-3.14" upper="3.14" velocity="1.2218"/>
  </joint>
  <link name="spherical_wrist_2_link">
    <inertial>
      <origin rpy="0 0 0" xyz="1E-06 -0.045483 -0.00965"/>
      <mass value="0.6781"/>
      <inertia ixx="0.001641" ixy="0" ixz="0" iyy="0.00041" iyz="-0.000278" izz="0.001641"/>
    </inertial>
    <visual>
      <origin rpy="0 0 0" xyz="0 0 0"/>
      <geometry>
        <mesh filename="meshes/7dof/spherical_wrist_2_link.STL"/>
      </geometry>
      <material name="">
        <color rgba="0.75294 0.75294 0.75294 1"/>
      </material>
    </visual>
    <collision>
      <origin rpy="0 0 0" xyz="0 0 0"/>
      <geometry>
        <mesh filename="meshes/7dof/spherical_wrist_2_link.STL"/>
      </geometry>
    </collision>
  </link>
  <joint name="joint_6" type="revolute">
    <origin rpy="1.5708 9.2076E-28 -8.2157E-15" xyz="0 0.00017505 -0.10593"/>
    <parent link="spherical_wrist_1_link"/>
    <child link="spherical_wrist_2_link"/>
    <axis xyz="0 0 1"/>
    <limit effort="9" lower="-2.09" upper="2.09" velocity="1.2218"/>
  </joint>
  <link name="bracelet_link">
    <inertial>
      <origin rpy="0 0 0" xyz="-9.3E-05 0.000132 -0.022905"/>
      <mass value="0.364"/>
      <inertia ixx="0.000214" ixy="0" ixz="1E-06" iyy="0.000223" iyz="-2E-06" izz="0.00024"/>
    </inertial>
    <visual>
      <origin rpy="0 0 0" xyz="0 0 0"/>
      <geometry>
        <mesh filename="meshes/7dof/bracelet_no_vision_link.STL"/>
      </geometry>
      <material name="">
        <color rgba="0.75294 0.75294 0.75294 1"/>
      </material>
    </visual>
    <collision>
      <origin rpy="0 0 0" xyz="0 0 0"/>
      <geometry>
        <mesh filename="meshes/7dof/bracelet_no_vision_link.STL"/>
      </geometry>
    </collision>
  </link>
  <joint name="joint_7" type="revolute">
    <origin rpy="-1.5708 -5.5511E-17 9.6396E-17" xyz="0 -0.10593 -0.00017505"/>
    <parent link="spherical_wrist_2_link"/>
    <child link="bracelet_link"/>
    <axis xyz="0 0 1"/>
    <limit effort="9" lower="-3.14" upper="3.14" velocity="1.2218"/>
  </joint>
  <link name="end_effector_link"/>
  <joint name="end_effector" type="fixed">
    <origin rpy="3.14159265358979 1.09937075168372E-32 0" xyz="0 0 -0.0615250000000001"/>
    <parent link="bracelet_link"/>
    <child link="end_effector_link"/>
    <axis xyz="0 0 0"/>
  </joint>
  <!-- Tool frame used by the arm -->
  <link name="tool_frame"/>
  <joint name="tool_frame_joint" type="fixed">
    <origin rpy="0 0 0" xyz="0 0 0.120"/>
    <parent link="end_effector_link"/>
    <child link="tool_frame"/>
    <axis xyz="0 0 0"/>
  </joint>
  <!-- This joint was added by Kinova -->
  <joint name="gripper_base_joint" type="fixed">
    <parent link="end_effector_link"/>
    <child link="robotiq_85_base_link"/>
    <origin rpy="0 -1.57079632679 -1.57079632679" xyz="0.0 0.0 0.0"/>
  </joint>

  <link name="robotiq_85_base_link">
    <visual>
      <geometry>
        <mesh filename="meshes/robotiq_85_gripper/visual/robotiq_85_base_link.dae"/>
      </geometry>
    </visual>
    <collision>
      <geometry>
        <mesh filename="meshes/robotiq_85_gripper/collision/robotiq_85_base_link.stl"/>
      </geometry>
    </collision>
    <inertial>
      <mass value="0.636951" />
      <origin xyz="0.0 0.0 0.0" />
      <inertia ixx = "0.000380" ixy = "0.000000" ixz = "0.000000"
            iyx = "0.000000" iyy = "0.001110" iyz = "0.000000"
            izx = "0.000000" izy = "0.000000" izz = "0.001171" />
    </inertial>
  </link>

  <!-- <joint name="robotiq_85_left_knuckle_joint" type="revolute"> -->
  <joint name="robotiq_85_left_knuckle_joint" type="fixed">
    <parent link="robotiq_85_base_link"/>
    <child link="robotiq_85_left_knuckle_link"/>
    <axis xyz="0 0 1"/>
    <origin rpy="3.14 0.0 0.0" xyz="0.05490451627 0.03060114443 0.0"/>
    <!-- <limit lower="0.0" upper="0.80285" velocity="3.14" effort="1000"/> -->
  </joint>

  <!-- <joint name="robotiq_85_right_knuckle_joint" type="revolute"> -->
  <joint name="robotiq_85_right_knuckle_joint" type="fixed">
    <parent link="robotiq_85_base_link"/>
    <child link="robotiq_85_right_knuckle_link"/>
    <axis xyz="0 0 1"/>
    <origin rpy="0.0 0.0 0.0" xyz="0.05490451627 -0.03060114443 0.0"/>
    <!-- <limit lower="-3.14" upper="3.14" velocity="3.14" effort="1000"/>
    <mimic joint="robotiq_85_left_knuckle_joint"/> -->
  </joint>

  <link name="robotiq_85_left_knuckle_link">
    <visual>
      <geometry>
        <mesh filename="meshes/robotiq_85_gripper/visual/robotiq_85_knuckle_link.dae"/>
      </geometry>
    </visual>
    <collision>
      <geometry>
        <mesh filename="meshes/robotiq_85_gripper/collision/robotiq_85_knuckle_link.stl"/>
      </geometry>
    </collision>
    <inertial>
      <mass value="0.018491" />
      <origin xyz="0.0 0.0 0.0" />
      <inertia ixx = "0.000009" ixy = "-0.000001" ixz = "0.000000"
            iyx = "-0.000001" iyy = "0.000001" iyz = "0.000000"
            izx = "0.000000" izy = "0.000000" izz = "0.000010" />
    </inertial>
  </link>

  <link name="robotiq_85_right_knuckle_link">
    <visual>
      <geometry>
        <mesh filename="meshes/robotiq_85_gripper/visual/robotiq_85_knuckle_link.dae"/>
      </geometry>
    </visual>
    <collision>
      <geometry>
        <mesh filename="meshes/robotiq_85_gripper/collision/robotiq_85_knuckle_link.stl"/>
      </geometry>
    </collision>
    <inertial>
      <mass value="0.018491" />
      <origin xyz="0.0 0.0 0.0" />
      <inertia ixx = "0.000009" ixy = "-0.000001" ixz = "0.000000"
            iyx = "-0.000001" iyy = "0.000001" iyz = "0.000000"
            izx = "0.000000" izy = "0.000000" izz = "0.000010" />
    </inertial>
  </link>

  <joint name="robotiq_85_left_finger_joint" type="fixed">
    <parent link="robotiq_85_left_knuckle_link"/>
    <child link="robotiq_85_left_finger_link"/>
    <origin xyz="-0.00408552455 -0.03148604435 0.0" rpy="0 0 0" />
  </joint>

  <joint name="robotiq_85_right_finger_joint" type="fixed">
    <parent link="robotiq_85_right_knuckle_link"/>
    <child link="robotiq_85_right_finger_link"/>
    <origin xyz="-0.00408552455 -0.03148604435 0.0" rpy="0 0 0" />
  </joint>

  <link name="robotiq_85_left_finger_link">
    <visual>
      <geometry>
        <mesh filename="meshes/robotiq_85_gripper/visual/robotiq_85_finger_link.dae"/>
      </geometry>
    </visual>
    <collision>
      <geometry>
        <mesh filename="meshes/robotiq_85_gripper/collision/robotiq_85_finger_link.stl"/>
      </geometry>
    </collision>
    <inertial>
      <mass value="0.027309" />
      <origin xyz="0.0 0.0 0.0" />
      <inertia ixx = "0.000003" ixy = "-0.000002" ixz = "0.000000"
            iyx = "-0.000002" iyy = "0.000021" iyz = "0.000000"
            izx = "0.000000" izy = "0.000000" izz = "0.000020" />
    </inertial>
  </link>

  <link name="robotiq_85_right_finger_link">
    <visual>
      <geometry>
        <mesh filename="meshes/robotiq_85_gripper/visual/robotiq_85_finger_link.dae"/>
      </geometry>
    </visual>
    <collision>
      <geometry>
        <mesh filename="meshes/robotiq_85_gripper/collision/robotiq_85_finger_link.stl"/>
      </geometry>
    </collision>
    <inertial>
      <mass value="0.027309" />
      <origin xyz="0.0 0.0 0.0" />
      <inertia ixx = "0.000003" ixy = "-0.000002" ixz = "0.000000"
            iyx = "-0.000002" iyy = "0.000021" iyz = "0.000000"
            izx = "0.000000" izy = "0.000000" izz = "0.000020" />
    </inertial>
  </link>

  <!-- <joint name="robotiq_85_left_inner_knuckle_joint" type="revolute"> -->
  <joint name="robotiq_85_left_inner_knuckle_joint" type="fixed">
    <parent link="robotiq_85_base_link"/>
    <child link="robotiq_85_left_inner_knuckle_link"/>
    <axis xyz="0 0 1"/>
    <origin xyz="0.06142 0.0127 0" rpy="3.14 0.0 0.0" />
    <!-- <limit lower="-3.14" upper="3.14" velocity="3.14" effort="0.1"/>
    <mimic joint="robotiq_85_left_knuckle_joint" offset="0"/> -->
  </joint>

  <!-- <joint name="robotiq_85_right_inner_knuckle_joint" type="revolute"> -->
  <joint name="robotiq_85_right_inner_knuckle_joint" type="fixed">
    <parent link="robotiq_85_base_link"/>
    <child link="robotiq_85_right_inner_knuckle_link"/>
    <axis xyz="0 0 1"/>
    <origin xyz="0.06142 -0.0127 0" rpy="0 0 0"/>
    <!-- <limit lower="-3.14" upper="3.14" velocity="3.14" effort="0.1"/>
    <mimic joint="robotiq_85_left_knuckle_joint" offset="0"/> -->
  </joint>

  <link name="robotiq_85_left_inner_knuckle_link">
    <visual>
      <geometry>
        <mesh filename="meshes/robotiq_85_gripper/visual/robotiq_85_inner_knuckle_link.dae"/>
      </geometry>
    </visual>
    <collision>
      <geometry>
        <mesh filename="meshes/robotiq_85_gripper/collision/robotiq_85_inner_knuckle_link.stl"/>
      </geometry>
    </collision>
    <inertial>
      <mass value="0.029951" />
      <origin xyz="0.0 0.0 0.0" />
      <inertia ixx = "0.000039" ixy = "0.000000" ixz = "0.000000"
            iyx = "0.000000" iyy = "0.000005" iyz = "0.000000"
            izx = "0.000000" izy = "0.000000" izz = "0.000035" />
    </inertial>
  </link>
  <link name="robotiq_85_right_inner_knuckle_link">
    <visual>
      <geometry>
        <mesh filename="meshes/robotiq_85_gripper/visual/robotiq_85_inner_knuckle_link.dae"/>
      </geometry>
    </visual>
    <collision>
      <geometry>
        <mesh filename="meshes/robotiq_85_gripper/collision/robotiq_85_inner_knuckle_link.stl"/>
      </geometry>
    </collision>
    <inertial>
      <mass value="0.029951" />
      <origin xyz="0.0 0.0 0.0" />
      <inertia ixx = "0.000039" ixy = "0.000000" ixz = "0.000000"
            iyx = "0.000000" iyy = "0.000005" iyz = "0.000000"
            izx = "0.000000" izy = "0.000000" izz = "0.000035" />
    </inertial>
  </link>

  <!-- <joint name="robotiq_85_left_finger_tip_joint" type="revolute"> -->
  <joint name="robotiq_85_left_finger_tip_joint" type="fixed">
    <parent link="robotiq_85_left_inner_knuckle_link"/>
    <child link="robotiq_85_left_finger_tip_link"/>
    <axis xyz="0 0 1"/>
    <origin xyz="0.04303959807 -0.03759940821 0.0" rpy="0.0 0.0 0.0"/>
    <!-- <limit lower="-3.14" upper="3.14" velocity="3.14" effort="0.1"/>
    <mimic joint="robotiq_85_left_knuckle_joint" multiplier="-1"/> -->
  </joint>

  <!-- <joint name="robotiq_85_right_finger_tip_joint" type="revolute"> -->
  <joint name="robotiq_85_right_finger_tip_joint" type="fixed">
    <parent link="robotiq_85_right_inner_knuckle_link"/>
    <child link="robotiq_85_right_finger_tip_link"/>
    <axis xyz="0 0 1"/>
    <origin rpy="0.0 0.0 0.0" xyz="0.04303959807 -0.03759940821  0.0"/>
    <!-- <limit lower="-3.14" upper="3.14" velocity="3.14" effort="0.1"/>
    <mimic joint="robotiq_85_left_knuckle_joint" multiplier="-1"/> -->
  </joint>

  <link name="robotiq_85_left_finger_tip_link">
    <visual>
      <geometry>
        <mesh filename="meshes/robotiq_85_gripper/visual/robotiq_85_finger_tip_link.dae"/>
      </geometry>
    </visual>
    <collision>
      <geometry>
        <mesh filename="meshes/robotiq_85_gripper/collision/robotiq_85_finger_tip_link.stl"/>
      </geometry>
    </collision>
    <inertial>
      <mass value="0.019555" />
      <origin xyz="0.0 0.0 0.0" />
      <inertia ixx = "0.000002" ixy = "0.000000" ixz = "0.000000"
            iyx = "0.000000" iyy = "0.000005" iyz = "0.000000"
            izx = "0.000000" izy = "0.000000" izz = "0.000006" />
    </inertial>
  </link>

  <link name="robotiq_85_right_finger_tip_link">
    <visual>
      <geometry>
        <mesh filename="meshes/robotiq_85_gripper/visual/robotiq_85_finger_tip_link.dae"/>
      </geometry>
    </visual>
    <collision>
      <geometry>
        <mesh filename="meshes/robotiq_85_gripper/collision/robotiq_85_finger_tip_link.stl"/>
      </geometry>
    </collision>
    <inertial>
      <mass value="0.019555" />
      <origin xyz="0.0 0.0 0.0" />
      <inertia ixx = "0.000002" ixy = "0.000000" ixz = "0.000000"
            iyx = "0.000000" iyy = "0.000005" iyz = "0.000000"
            izx = "0.000000" izy = "0.000000" izz = "0.000006" />
    </inertial>
  </link>

  <link name="gripper_base_target">
    <visual>
      <geometry>
        <sphere radius="0.01"/>
      </geometry>
    </visual>
  </link>
  <joint name="gripper_parent_to_target" type="fixed">
    <origin rpy="0 0 -1.57079632679" xyz="0 0 0.045"/>
    <parent link="end_effector_link"/>
    <child link="gripper_base_target"/>
    <axis xyz="0 0 0"/>
  </joint>

</robot>

